<?xml version="1.0"?>
<robot name="conveyor_belt2">

<!-- conveyor belt is just a long flat box for objects to slide on it -->

<!-- world link -->
<link name="world"/>

<!-- base_link and its fixed joint -->
	<joint name="fixed" type="fixed">
		<parent link="world"/>
		<child link="belt_visual"/>
		<origin xyz="0.9 0.325 0.0" rpy="0.0 0.0 -1.5708"/>
	</joint>
	

	<link name="belt_visual">
		<inertial>
			<origin xyz="1.1327E-16 -3.3286E-17 0.58819" rpy="0 0 0" />
			<mass value="71.953" />
			<inertia ixx="7.5972" ixy="-1.394E-14" ixz="1.9328E-17" iyy="0.99673" iyz="-9.2056E-18" izz="8.1168" />
		</inertial>
		<visual>
			<origin xyz="0 0 0" rpy="0 0 0" />
			<geometry>
				<mesh filename="package://gantry/meshes/conveyor_belt.dae" />
			</geometry>
			<material name="blue">
				<color rgba="0.8 0.325 0.06 1" />
			</material>
		</visual>
		<collision>
			<origin xyz="0.0 0.0 0" rpy="1.570796327 0.0 1.570796327"/>
			<geometry>
				<mesh filename="package://gantry/meshes/conveyor_simple.dae" />
			</geometry>
		</collision>
	</link>

	<!-- <link name="test_cube">
		<visual>
			<origin xyz="0.0 0.0 0.37" rpy="0.0 0.0 0.0"/>
			<geometry>
				<box size="0.463 1.2 0.74"/>
			</geometry>
			<material name="purple">
				<color rgba="1 0 1 0.2" />
			</material>
		</visual>
	</link> -->

	<joint name="belt_joint" type="prismatic">
		<origin xyz="0.0 0.0 0.589" rpy="0.0 0.0 0.0"/>
		<parent link="belt_visual"/>
		<child link="belt_moving"/>
		<axis xyz="0 -1 0"/>
		<limit lower="0.0" upper="1" effort="1000" velocity="1000"/>
	</joint>

	<link name="belt_moving">
		<inertial>
			<origin xyz="0.0 0.0 0.0" rpy="0.0 0.0 0.0"/>
			<mass value="100"/>
			<inertia ixx="1.0" ixy="0.0" ixz="0.0" iyy="1.0" iyz="0.0" izz="1.0"/>
		</inertial>
		<!-- <visual>
			<origin xyz="0.0 0.0 0.0005" rpy="0.0 0.0 0.0"/>
			<geometry>
				<box size="0.425 1.2 0.001"/>
			</geometry>
			<material name="test">
				<color rgba="1 0 1 1" />
			</material>
		</visual> -->
		<collision>
			<origin xyz="0.0 0.5 0.0005" rpy="0.0 0.0 0.0"/>
			<geometry>
				<box size="0.425 3.85 0.001"/>
			</geometry>
		</collision>
	</link>
	<link name="Big_box">
        
	<inertial>
            <origin xyz="-2.6593E-06 5.7892E-06 0.0070718" rpy="0 0 0" />
            <mass value="20.128" />
            <inertia ixx="6.7515" ixy="-2.2805" ixz="1.831" iyy="6.7541" iyz="-9.4715" izz="6.9139" />
        </inertial>

        <visual>
            <origin xyz="0 0 0" rpy="0 0 0" />
            <geometry>
                <mesh filename="package://gantry/meshes/Big_box.dae" />
            </geometry>
            <material name="">
                <color rgba="0.79216 0.81961 0.93333 1" />
            </material>
        </visual>
        <!-- <collision>
            <origin xyz="0 0 0" rpy="0 0 0" />
            <geometry>
                <mesh filename="package://gantry/meshes/Big_box.dae" />
            </geometry>
        </collision> -->
    </link>
    <joint name="Big_box_Joint" type="fixed">
        <origin xyz="0.4 0.325 0.69" rpy="0 -1.5708 1.5708" />
        <parent link="world" />
        <child link="Big_box" />
        <axis xyz="0 0 1" />
    </joint>
	<link name="Big_box2">
        
	<inertial>
            <origin xyz="-2.6593E-06 5.7892E-06 0.0070718" rpy="0 0 0" />
            <mass value="20.128" />
            <inertia ixx="6.7515" ixy="-2.2805" ixz="1.831" iyy="6.7541" iyz="-9.4715" izz="6.9139" />
        </inertial>

        <visual>
            <origin xyz="0 0 0" rpy="0 0 0" />
            <geometry>
                <mesh filename="package://gantry/meshes/Big_box.dae" />
            </geometry>
            <material name="">
                <color rgba="0.79216 0.81961 0.93333 1" />
            </material>
        </visual>
        <!-- <collision>
            <origin xyz="0 0 0" rpy="0 0 0" />
            <geometry>
                <mesh filename="package://gantry/meshes/Big_box.dae" />
            </geometry>
        </collision> -->
    </link>
    <joint name="Big_box_Joint2" type="fixed">
        <origin xyz="-0.275 0.325 0.69" rpy="0 -1.5708 1.5708" />
        <parent link="world" />
        <child link="Big_box2" />
        <axis xyz="0 0 1" />
    </joint>
    <gazebo>
     <plugin name="conveyor_belt_plugin" filename="libROSConveyorBeltPlugin.so">
        <robot_namespace>/</robot_namespace>
        <link>belt_moving</link>
        <update_rate>10</update_rate>
        <power>10</power>
        <max_velocity>10.2</max_velocity>
     </plugin>
     <mu1>0</mu1>
     <mu2>0</mu2>
     <material>Gazebo/FlatBlack</material>
    </gazebo>
  <!--<gazebo reference="belt_visual">
	<material>Gazebo/Blue</material>
  </gazebo>-->

</robot>
