<?xml version="1.0" encoding="utf-8"?>
<!-- This URDF was automatically created by SolidWorks to URDF Exporter! Originally created by Stephen Brawner (brawner@gmail.com) 
     Commit Version: 1.6.0-1-g15f4949  Build Version: 1.6.7594.29634
     For more information, please see http://wiki.ros.org/sw_urdf_exporter -->
<!--<robot
  name="gantry">
  <link
    name="base_link">
    <inertial>
      <origin
        xyz="0.96371 1.032 1.4293"
        rpy="0 0 0" />
      <mass
        value="18.891" />
      <inertia
        ixx="0.68505"
        ixy="4.644E-15"
        ixz="5.1723E-15"
        iyy="1.4324"
        iyz="-4.7026E-17"
        izz="2.0528" />
    </inertial>
    <visual>
      <origin
        xyz="0 0 0"
        rpy="0 0 0" />
      <geometry>
        <mesh
          filename="package://gantry/meshes/base_link.STL" />
      </geometry>
      <material
        name="">
        <color
          rgba="0.79216 0.81961 0.93333 1" />
      </material>
    </visual>
    <collision>
      <origin
        xyz="0 0 0"
        rpy="0 0 0" />
      <geometry>
        <mesh
          filename="package://gantry/meshes/base_link.STL" />
      </geometry>
    </collision>
  </link>
  <link
    name="X_Motion">
    <inertial>
      <origin
        xyz="0.2743 0.98859 0.047316"
        rpy="0 0 0" />
      <mass
        value="12.196" />
      <inertia
        ixx="1.9209"
        ixy="8.6077E-06"
        ixz="-1.8748E-08"
        iyy="1.9628"
        iyz="4.3927E-15"
        izz="0.060176" />
    </inertial>
    <visual>
      <origin
        xyz="0 0 0"
        rpy="0 0 0" />
      <geometry>
        <mesh
          filename="package://gantry/meshes/X_Motion.STL" />
      </geometry>
      <material
        name="">
        <color
          rgba="0.79216 0.81961 0.93333 1" />
      </material>
    </visual>
    <collision>
      <origin
        xyz="0 0 0"
        rpy="0 0 0" />
      <geometry>
        <mesh
          filename="package://gantry/meshes/X_Motion.STL" />
      </geometry>
    </collision>
  </link>
  <joint
    name="X_Joint"
    type="prismatic">
    <origin
      xyz="-0.3 0.05 0.195"
      rpy="1.5708 0 1.5708" />
    <parent
      link="base_link" />
    <child
      link="X_Motion" />
    <axis
      xyz="0 0 1" />
    <limit
      lower="-0.45"
      upper="0.48"
      effort="20"
      velocity="1" />
  </joint>
  <link
    name="Y_Motion">
    <inertial>
      <origin
        xyz="0.060449 1.3458 0.1606"
        rpy="0 0 0" />
      <mass
        value="5.302" />
      <inertia
        ixx="0.061782"
        ixy="1.534E-08"
        ixz="-3.3824E-14"
        iyy="0.016124"
        iyz="-2.88E-05"
        izz="0.065933" />
    </inertial>
    <visual>
      <origin
        xyz="0 0 0"
        rpy="0 0 0" />
      <geometry>
        <mesh
          filename="package://gantry/meshes/Y_Motion.STL" />
      </geometry>
      <material
        name="">
        <color
          rgba="0.79216 0.81961 0.93333 1" />
      </material>
    </visual>
    <collision>
      <origin
        xyz="0 0 0"
        rpy="0 0 0" />
      <geometry>
        <mesh
          filename="package://gantry/meshes/Y_Motion.STL" />
      </geometry>
    </collision>
  </link>
  <joint
    name="Y_Joint"
    type="prismatic">
    <origin
      xyz="0.1 0 0.21"
      rpy="0 -1.5708 0" />
    <parent
      link="X_Motion" />
    <child
      link="Y_Motion" />
    <axis
      xyz="0 0 1" />
    <limit
      lower="-0.4"
      upper="0.4"
      effort="10"
      velocity="1" />
  </joint>
  <link
    name="Z_Motion">
    <inertial>
      <origin
        xyz="0.241 0.1282 0.0031489"
        rpy="0 0 0" />
      <mass
        value="1.6351" />
      <inertia
        ixx="0.0038426"
        ixy="4.3556E-06"
        ixz="3.0941E-18"
        iyy="0.002377"
        iyz="-1.5732E-18"
        izz="0.0032352" />
    </inertial>
    <visual>
      <origin
        xyz="0 0 0"
        rpy="0 0 0" />
      <geometry>
        <mesh
          filename="package://gantry/meshes/Z_Motion.STL" />
      </geometry>
      <material
        name="">
        <color
          rgba="0.79216 0.81961 0.93333 1" />
      </material>
    </visual>
    <collision>
      <origin
        xyz="0 0 0"
        rpy="0 0 0" />
      <geometry>
        <mesh
          filename="package://gantry/meshes/Z_Motion.STL" />
      </geometry>
    </collision>
  </link>
  <joint
    name="Z_Joint"
    type="prismatic">
    <origin
      xyz="-0.0115 1.1071 0.19185"
      rpy="-1.5708 0 0" />
    <parent
      link="Y_Motion" />
    <child
      link="Z_Motion" />
    <axis
      xyz="0 0 1" />
    <limit
      lower="-0.2"
      upper="0.2"
      effort="5"
      velocity="1" />
  </joint>
  <link
    name="Z_Rot">
    <inertial>
      <origin
        xyz="2.9681E-06 -0.2854 -7.323E-05"
        rpy="0 0 0" />
      <mass
        value="0.45277" />
      <inertia
        ixx="0.0077144"
        ixy="1.8825E-18"
        ixz="1.0049E-05"
        iyy="0.00045474"
        iyz="-2.4954E-17"
        izz="0.0074669" />
    </inertial>
    <visual>
      <origin
        xyz="0 0 0"
        rpy="0 0 0" />
      <geometry>
        <mesh
          filename="package://gantry/meshes/Z_Rot.STL" />
      </geometry>
      <material
        name="">
        <color
          rgba="0.79216 0.81961 0.93333 1" />
      </material>
    </visual>
    <collision>
      <origin
        xyz="0 0 0"
        rpy="0 0 0" />
      <geometry>
        <mesh
          filename="package://gantry/meshes/Z_Rot.STL" />
      </geometry>
    </collision>
  </link>
  <joint
    name="Z_Rot_Joint"
    type="revolute">
    <origin
      xyz="0.25743 0 0.0031492"
      rpy="0 0 0" />
    <parent
      link="Z_Motion" />
    <child
      link="Z_Rot" />
    <axis
      xyz="0 0 1" />
    <limit
      lower="-3.14"
      upper="3.14"
      effort="5"
      velocity="1" />
  </joint>
  <link
    name="Cup">
    <inertial>
      <origin
        xyz="-2.6593E-06 5.7892E-06 0.0070718"
        rpy="0 0 0" />
      <mass
        value="0.0020128" />
      <inertia
        ixx="6.7515E-08"
        ixy="-2.2805E-12"
        ixz="1.831E-12"
        iyy="6.7541E-08"
        iyz="-9.4715E-13"
        izz="6.9139E-08" />
    </inertial>
    <visual>
      <origin
        xyz="0 0 0"
        rpy="0 0 0" />
      <geometry>
        <mesh
          filename="package://gantry/meshes/Cup.STL" />
      </geometry>
      <material
        name="">
        <color
          rgba="0.79216 0.81961 0.93333 1" />
      </material>
    </visual>
    <collision>
      <origin
        xyz="0 0 0"
        rpy="0 0 0" />
      <geometry>
        <mesh
          filename="package://gantry/meshes/Cup.STL" />
      </geometry>
    </collision>
  </link>
  <joint
    name="Cup_Joint"
    type="fixed">
    <origin
      xyz="-0.0 -0.05 -0.48"
      rpy="3.1416 -0.0 0" />
    <parent
      link="Z_Rot" />
    <child
      link="Cup" />
    <axis
      xyz="0 0 1" />
  </joint>
</robot>-->


<!-- This URDF was automatically created by SolidWorks to URDF Exporter! Originally created by Stephen Brawner (brawner@gmail.com) 
     Commit Version: 1.6.0-1-g15f4949  Build Version: 1.6.7594.29634
     For more information, please see http://wiki.ros.org/sw_urdf_exporter -->
<robot name="gantry">

    <link name="world" />
    <joint name="Fix_Joint" type="fixed">
        <origin xyz="-0.0 0.00 0.0" rpy="0 0 0" />
        <parent link="world" />
        <child link="base_link" />
        <axis xyz="0 0 1" />
    </joint>
    <link name="base_link">
        
<inertial>
            <origin xyz="0.96371 1.032 1.4293" rpy="0 0 0" />
            <mass value="18.891" />
            <inertia ixx="0.68505" ixy="4.644E-15" ixz="5.1723E-15" iyy="1.4324" iyz="-4.7026E-17" izz="2.0528" />
        </inertial>

        <visual>
            <origin xyz="0 0 0" rpy="0 0 0" />
            <geometry>
                <mesh filename="package://gantry/meshes/base_link.dae" />
            </geometry>
            <material name="">
                <color rgba="0.79216 0.81961 0.93333 1" />
            </material>
        </visual>
        <collision>
            <origin xyz="0 0 0" rpy="0 0 0" />
            <geometry>
                <mesh filename="package://gantry/meshes/base_link.dae" />
            </geometry>
        </collision>
    </link>
    <link name="X_Motion">
        
<inertial>
            <origin xyz="0.2743 0.98859 0.047316" rpy="0 0 0" />
            <mass value="12.196" />
            <inertia ixx="1.9209" ixy="8.6077E-06" ixz="-1.8748E-08" iyy="1.9628" iyz="4.3927E-15" izz="0.060176" />
        </inertial>

        <visual>
            <origin xyz="0 0 0" rpy="0 0 0" />
            <geometry>
                <mesh filename="package://gantry/meshes/X_Motion.dae" />
            </geometry>
            <material name="">
                <color rgba="0.79216 0.81961 0.93333 1" />
            </material>
        </visual>
        <collision>
            <origin xyz="0 0 0" rpy="0 0 0" />
            <geometry>
                <mesh filename="package://gantry/meshes/X_Motion.dae" />
            </geometry>
        </collision>
    </link>
    <joint name="X_Joint" type="prismatic">
        <origin xyz="-0.3 0.05 0.195" rpy="1.5708 0 1.5708" />
        <parent link="base_link" />
        <child link="X_Motion" />
        <axis xyz="0 0 1" />
        <limit lower="-0.45" upper="0.48" effort="20" velocity="1" />
    </joint>
    <link name="Y_Motion">
        
<inertial>
            <origin xyz="0.060449 1.3458 0.1606" rpy="0 0 0" />
            <mass value="5.302" />
            <inertia ixx="0.061782" ixy="1.534E-08" ixz="-3.3824E-14" iyy="0.016124" iyz="-2.88E-05" izz="0.065933" />
        </inertial>

        <visual>
            <origin xyz="0 0 0" rpy="0 0 0" />
            <geometry>
                <mesh filename="package://gantry/meshes/Y_Motion.dae" />
            </geometry>
            <material name="">
                <color rgba="0.79216 0.81961 0.93333 1" />
            </material>
        </visual>
        <collision>
            <origin xyz="0 0 0" rpy="0 0 0" />
            <geometry>
                <mesh filename="package://gantry/meshes/Y_Motion.dae" />
            </geometry>
        </collision>
    </link>
    <joint name="Y_Joint" type="prismatic">
        <origin xyz="0.1 0 0.21" rpy="0 -1.5708 0" />
        <parent link="X_Motion" />
        <child link="Y_Motion" />
        <axis xyz="0 0 1" />
        <limit lower="-0.4" upper="0.4" effort="10" velocity="1" />
    </joint>
    <link name="Z_Motion">
        
<inertial>
            <origin xyz="0.241 0.1282 0.0031489" rpy="0 0 0" />
            <mass value="1.0351" />
            <inertia ixx="0.0038426" ixy="4.3556E-06" ixz="3.0941E-18" iyy="0.002377" iyz="-1.5732E-18" izz="0.0032352" />
        </inertial>

        <visual>
            <origin xyz="0 0 0" rpy="0 0 0" />
            <geometry>
                <mesh filename="package://gantry/meshes/Z_Motion.dae" />
            </geometry>
            <material name="">
                <color rgba="0.79216 0.81961 0.93333 1" />
            </material>
        </visual>
        <collision>
            <origin xyz="0 0 0" rpy="0 0 0" />
            <geometry>
                <mesh filename="package://gantry/meshes/Z_Motion.dae" />
            </geometry>
        </collision>
    </link>
    <joint name="Z_Joint" type="prismatic">
        <origin xyz="-0.0115 1.1071 0.19185" rpy="-1.5708 0 0" />
        <parent link="Y_Motion" />
        <child link="Z_Motion" />
        <axis xyz="0 0 1" />
        <limit lower="-0.2" upper="0.2" effort="50" velocity="1" />
    </joint>
    <link name="Z_Rot">
        
<inertial>
            <origin xyz="2.9681E-06 -0.2854 -7.323E-05" rpy="0 0 0" />
            <mass value="0.15277" />
            <inertia ixx="0.0077144" ixy="1.8825E-18" ixz="1.0049E-05" iyy="0.00045474" iyz="-2.4954E-17" izz="0.0074669" />
        </inertial>

        <visual>
            <origin xyz="0 0 0" rpy="0 0 0" />
            <geometry>
                <mesh filename="package://gantry/meshes/Z_Rot.dae" />
            </geometry>
            <material name="">
                <color rgba="0.79216 0.81961 0.93333 1" />
            </material>
        </visual>
        <collision>
            <origin xyz="0 0 0" rpy="0 0 0" />
            <geometry>
                <mesh filename="package://gantry/meshes/Z_Rot.dae" />
            </geometry>
        </collision>
    </link>
    <joint name="Z_Rot_Joint" type="revolute">
        <origin xyz="0.25743 0 0.0031492" rpy="0 0 0" />
        <parent link="Z_Motion" />
        <child link="Z_Rot" />
        <axis xyz="0 0 1" />
        <limit lower="-3.14" upper="3.14" effort="5" velocity="1" />
    </joint>
    <link name="Cup">
        
<inertial>
            <origin xyz="-2.6593E-06 5.7892E-06 0.0070718" rpy="0 0 0" />
            <mass value="0.0020128" />
            <inertia ixx="6.7515E-08" ixy="-2.2805E-12" ixz="1.831E-12" iyy="6.7541E-08" iyz="-9.4715E-13" izz="6.9139E-08" />
        </inertial>

        <visual>
            <origin xyz="0 0 0" rpy="0 0 0" />
            <geometry>
                <mesh filename="package://gantry/meshes/Cup.dae" />
            </geometry>
            <material name="">
                <color rgba="0.79216 0.81961 0.93333 1" />
            </material>
        </visual>
        <collision>
            <origin xyz="0 0 0" rpy="0 0 0" />
            <geometry>
                <mesh filename="package://gantry/meshes/Cup.dae" />
            </geometry>
        </collision>
    </link>
    <joint name="Cup_Joint" type="fixed">
        <origin xyz="-0.0 -0.05 -0.48" rpy="3.1416 -0.0 0" />
        <parent link="Z_Rot" />
        <child link="Cup" />
        <axis xyz="0 0 1" />
    </joint>
  <joint name="camera_joint" type="fixed">
    <axis xyz="0 1 0" />
    <origin xyz="1.8 -0.375 1.0" rpy="0 1.5708 0"/>
    <parent link="world"/>
    <child link="camera_link"/>
  </joint>

  <!-- Camera -->
  <link name="camera_link">
    <collision>
      <origin xyz="0 0 0" rpy="0 0 0"/>
      <geometry>
    <box size="0.01 0.01 0.01"/>
      </geometry>
    </collision>

    <visual>
      <origin xyz="0 0 0" rpy="0 0 0"/>
      <geometry>
    <box size="0.01 0.01 0.01"/>
      </geometry>
      
    </visual>

    <inertial>
      <mass value="1e-5" />
      <origin xyz="0 0 0" rpy="0 0 0"/>
      <inertia ixx="1e-6" ixy="0" ixz="0" iyy="1e-6" iyz="0" izz="1e-6" />
    </inertial>
  </link>   
  
  <joint name="laser_joint" type="fixed">
    <axis xyz="0 1 0" />
    <origin xyz="1 -0.375 1.0" rpy="0 1.5708 0"/>
    <parent link="world"/>
    <child link="laser_link"/>
  </joint>

  <!-- Hokuyo Laser -->
  <link name="laser_link">
    <collision>
      <origin xyz="0 0 0" rpy="0 0 0"/>
      <geometry>
    <box size="0.01 0.01 0.01"/>
      </geometry>
    </collision>

    <visual>
      <origin xyz="0 0 0" rpy="0 0 0"/>
      <geometry>
        <box size="0.01 0.01 0.01"/>
      </geometry>
    </visual>

    <inertial>
      <mass value="1e-5" />
      <origin xyz="0 0 0" rpy="0 0 0"/>
      <inertia ixx="1e-6" ixy="0" ixz="0" iyy="1e-6" iyz="0" izz="1e-6" />
    </inertial>
  </link>
  
  <joint name="cam_on_laser_joint" type="fixed">
    <axis xyz="0 1 0" />
    <origin xyz="1.8 -0.75 0.7" rpy="0 0 1.5708"/>
    <parent link="world"/>
    <child link="cam_on_laser_link"/>
  </joint>

  <!-- Hokuyo Laser -->
  <link name="cam_on_laser_link">
    <collision>
      <origin xyz="0 0 0" rpy="0 0 0"/>
      <geometry>
    <box size="0.01 0.01 0.01"/>
      </geometry>
    </collision>

    <visual>
      <origin xyz="0 0 0" rpy="0 0 0"/>
      <geometry>
        <box size="0.01 0.01 0.01"/>
      </geometry>
    </visual>

    <inertial>
      <mass value="1e-5" />
      <origin xyz="0 0 0" rpy="0 0 0"/>
      <inertia ixx="1e-6" ixy="0" ixz="0" iyy="1e-6" iyz="0" izz="1e-6" />
    </inertial>
  </link>   
  
  
<transmission name="trans_X_Joint">
        <type>transmission_interface/SimpleTransmission</type>
        <joint name="X_Joint">
            <hardwareInterface>hardware_interface/PositionJointInterface</hardwareInterface>
        </joint>
        <actuator name="X_Joint_motor">
            <hardwareInterface>hardware_interface/PositionJointInterface</hardwareInterface>
            <mechanicalReduction>1</mechanicalReduction>
        </actuator>
    </transmission>
    <transmission name="trans_Y_Joint">
        <type>transmission_interface/SimpleTransmission</type>
        <joint name="Y_Joint">
            <hardwareInterface>hardware_interface/PositionJointInterface</hardwareInterface>
        </joint>
        <actuator name="Y_Joint_motor">
            <hardwareInterface>hardware_interface/PositionJointInterface</hardwareInterface>
            <mechanicalReduction>1</mechanicalReduction>
        </actuator>
    </transmission>
    <transmission name="trans_Z_Joint">
        <type>transmission_interface/SimpleTransmission</type>
        <joint name="Z_Joint">
            <hardwareInterface>hardware_interface/PositionJointInterface</hardwareInterface>
        </joint>
        <actuator name="Z_Joint_motor">
            <hardwareInterface>hardware_interface/PositionJointInterface</hardwareInterface>
            <mechanicalReduction>1</mechanicalReduction>
        </actuator>
    </transmission>
    <transmission name="trans_Z_Rot_Joint">
        <type>transmission_interface/SimpleTransmission</type>
        <joint name="Z_Rot_Joint">
            <hardwareInterface>hardware_interface/PositionJointInterface</hardwareInterface>
        </joint>
        <actuator name="Z_Rot_Joint_motor">
            <hardwareInterface>hardware_interface/PositionJointInterface</hardwareInterface>
            <mechanicalReduction>1</mechanicalReduction>
        </actuator>
    </transmission>
    <gazebo>
        <plugin name="gazebo_ros_control" filename="libgazebo_ros_control.so">
            <robotNamespace>/</robotNamespace>
        </plugin>
    </gazebo>
    <gazebo reference="camera_link">
    	<material>Gazebo/Red</material>
    </gazebo>
  <gazebo reference="camera_link">
    <sensor type="camera" name="camera1">
      <update_rate>30.0</update_rate>
      <camera name="head">
        <horizontal_fov>1.3962634</horizontal_fov>
        <image>
          <width>800</width>
          <height>800</height>
          <format>R8G8B8</format>
        </image>
        <clip>
          <near>0.02</near>
          <far>300</far>
        </clip>
        <noise>
          <type>gaussian</type>
          <!-- Noise is sampled independently per pixel on each frame.
               That pixel's noise value is added to each of its color
               channels, which at that point lie in the range [0,1]. -->
          <mean>0.0</mean>
          <stddev>0.007</stddev>
        </noise>
      </camera>
      <plugin name="camera_controller" filename="libgazebo_ros_camera.so">
        <alwaysOn>true</alwaysOn>
        <updateRate>0.0</updateRate>
        <cameraName>/camera1</cameraName>
        <imageTopicName>/camera1/image_raw</imageTopicName>
        <cameraInfoTopicName>/camera1/camera_info</cameraInfoTopicName>
        <frameName>camera_link</frameName>
        <hackBaseline>0.07</hackBaseline>
        <distortionK1>0.0</distortionK1>
        <distortionK2>0.0</distortionK2>
        <distortionK3>0.0</distortionK3>
        <distortionT1>0.0</distortionT1>
        <distortionT2>0.0</distortionT2>
      </plugin>
    </sensor>
  </gazebo>  
  
  <gazebo reference="laser_link">
    <material>Gazebo/Red</material>
    <sensor type="ray" name="head_laser_sensor">
      <pose>0 0 0 0 0 0</pose>
      <always_on>1</always_on>
      <visualize>true</visualize>
      <update_rate>20</update_rate>
      <ray>
        <scan>
          <horizontal>
            <samples>1</samples>
            <resolution>1</resolution>
            <min_angle>-0.0</min_angle>
            <max_angle>0.0</max_angle>
          </horizontal>
        </scan>
        <range>
          <min>0.08</min>
          <max>3.0</max>
          <resolution>0.01</resolution>
        </range>
        <noise>
          <type>gaussian</type>
          <!-- Noise parameters based on published spec for Hokuyo laser
               achieving "+-30mm" accuracy at range < 10m.  A mean of 0.0m and
               stddev of 0.01m will put 99.7% of samples within 0.03m of the true
               reading. -->
          <mean>0.0</mean>
          <stddev>0.01</stddev>
        </noise>
      </ray>
      <plugin name="gazebo_ros_head_laser_controller" filename="libgazebo_ros_laser.so">
        <topicName>/laser/scan</topicName>
        <frameName>/world</frameName>
      </plugin>
    </sensor>
  </gazebo>   
  
  <gazebo reference="cam_on_laser_link">
    <material>Gazebo/Red</material>
    <sensor type="ray" name="head_laser_sensor_2">
      <pose>0 0 0 0 0 0</pose>
      <always_on>1</always_on>
      <visualize>true</visualize>
      <update_rate>20</update_rate>
      <ray>
        <scan>
          <horizontal>
            <samples>1</samples>
            <resolution>1</resolution>
            <min_angle>-0.0</min_angle>
            <max_angle>0.0</max_angle>
          </horizontal>
        </scan>
        <range>
          <min>0.08</min>
          <max>0.8</max>
          <resolution>0.01</resolution>
        </range>
        <noise>
          <type>gaussian</type>
          <!-- Noise parameters based on published spec for Hokuyo laser
               achieving "+-30mm" accuracy at range < 10m.  A mean of 0.0m and
               stddev of 0.01m will put 99.7% of samples within 0.03m of the true
               reading. -->
          <mean>0.0</mean>
          <stddev>0.01</stddev>
        </noise>
      </ray>
      <plugin name="gazebo_ros_head_laser_controller" filename="libgazebo_ros_laser.so">
        <topicName>/cam_on_laser/scan</topicName>
        <frameName>/world</frameName>
      </plugin>
    </sensor>
  </gazebo>   

</robot>









<!-- END -->
