<?xml version="1.0" encoding="utf-8"?>
<!-- This URDF was automatically created by SolidWorks to URDF Exporter! Originally created by Stephen Brawner (brawner@gmail.com) 
     Commit Version: 1.6.0-1-g15f4949  Build Version: 1.6.7594.29634
     For more information, please see http://wiki.ros.org/sw_urdf_exporter -->
<!--<robot
  name="gantry">
  <link
    name="base_link">
    <inertial>
      <origin
        xyz="0.96371 1.032 1.4293"
        rpy="0 0 0" />
      <mass
        value="18.891" />
      <inertia
        ixx="0.68505"
        ixy="4.644E-15"
        ixz="5.1723E-15"
        iyy="1.4324"
        iyz="-4.7026E-17"
        izz="2.0528" />
    </inertial>
    <visual>
      <origin
        xyz="0 0 0"
        rpy="0 0 0" />
      <geometry>
        <mesh
          filename="package://gantry/meshes/base_link.STL" />
      </geometry>
      <material
        name="">
        <color
          rgba="0.79216 0.81961 0.93333 1" />
      </material>
    </visual>
    <collision>
      <origin
        xyz="0 0 0"
        rpy="0 0 0" />
      <geometry>
        <mesh
          filename="package://gantry/meshes/base_link.STL" />
      </geometry>
    </collision>
  </link>
  <link
    name="X_Motion">
    <inertial>
      <origin
        xyz="0.2743 0.98859 0.047316"
        rpy="0 0 0" />
      <mass
        value="12.196" />
      <inertia
        ixx="1.9209"
        ixy="8.6077E-06"
        ixz="-1.8748E-08"
        iyy="1.9628"
        iyz="4.3927E-15"
        izz="0.060176" />
    </inertial>
    <visual>
      <origin
        xyz="0 0 0"
        rpy="0 0 0" />
      <geometry>
        <mesh
          filename="package://gantry/meshes/X_Motion.STL" />
      </geometry>
      <material
        name="">
        <color
          rgba="0.79216 0.81961 0.93333 1" />
      </material>
    </visual>
    <collision>
      <origin
        xyz="0 0 0"
        rpy="0 0 0" />
      <geometry>
        <mesh
          filename="package://gantry/meshes/X_Motion.STL" />
      </geometry>
    </collision>
  </link>
  <joint
    name="X_Joint"
    type="prismatic">
    <origin
      xyz="-0.3 0.05 0.195"
      rpy="1.5708 0 1.5708" />
    <parent
      link="base_link" />
    <child
      link="X_Motion" />
    <axis
      xyz="0 0 1" />
    <limit
      lower="-0.45"
      upper="0.48"
      effort="20"
      velocity="1" />
  </joint>
  <link
    name="Y_Motion">
    <inertial>
      <origin
        xyz="0.060449 1.3458 0.1606"
        rpy="0 0 0" />
      <mass
        value="5.302" />
      <inertia
        ixx="0.061782"
        ixy="1.534E-08"
        ixz="-3.3824E-14"
        iyy="0.016124"
        iyz="-2.88E-05"
        izz="0.065933" />
    </inertial>
    <visual>
      <origin
        xyz="0 0 0"
        rpy="0 0 0" />
      <geometry>
        <mesh
          filename="package://gantry/meshes/Y_Motion.STL" />
      </geometry>
      <material
        name="">
        <color
          rgba="0.79216 0.81961 0.93333 1" />
      </material>
    </visual>
    <collision>
      <origin
        xyz="0 0 0"
        rpy="0 0 0" />
      <geometry>
        <mesh
          filename="package://gantry/meshes/Y_Motion.STL" />
      </geometry>
    </collision>
  </link>
  <joint
    name="Y_Joint"
    type="prismatic">
    <origin
      xyz="0.1 0 0.21"
      rpy="0 -1.5708 0" />
    <parent
      link="X_Motion" />
    <child
      link="Y_Motion" />
    <axis
      xyz="0 0 1" />
    <limit
      lower="-0.4"
      upper="0.4"
      effort="10"
      velocity="1" />
  </joint>
  <link
    name="Z_Motion">
    <inertial>
      <origin
        xyz="0.241 0.1282 0.0031489"
        rpy="0 0 0" />
      <mass
        value="1.6351" />
      <inertia
        ixx="0.0038426"
        ixy="4.3556E-06"
        ixz="3.0941E-18"
        iyy="0.002377"
        iyz="-1.5732E-18"
        izz="0.0032352" />
    </inertial>
    <visual>
      <origin
        xyz="0 0 0"
        rpy="0 0 0" />
      <geometry>
        <mesh
          filename="package://gantry/meshes/Z_Motion.STL" />
      </geometry>
      <material
        name="">
        <color
          rgba="0.79216 0.81961 0.93333 1" />
      </material>
    </visual>
    <collision>
      <origin
        xyz="0 0 0"
        rpy="0 0 0" />
      <geometry>
        <mesh
          filename="package://gantry/meshes/Z_Motion.STL" />
      </geometry>
    </collision>
  </link>
  <joint
    name="Z_Joint"
    type="prismatic">
    <origin
      xyz="-0.0115 1.1071 0.19185"
      rpy="-1.5708 0 0" />
    <parent
      link="Y_Motion" />
    <child
      link="Z_Motion" />
    <axis
      xyz="0 0 1" />
    <limit
      lower="-0.2"
      upper="0.2"
      effort="5"
      velocity="1" />
  </joint>
  <link
    name="Z_Rot">
    <inertial>
      <origin
        xyz="2.9681E-06 -0.2854 -7.323E-05"
        rpy="0 0 0" />
      <mass
        value="0.45277" />
      <inertia
        ixx="0.0077144"
        ixy="1.8825E-18"
        ixz="1.0049E-05"
        iyy="0.00045474"
        iyz="-2.4954E-17"
        izz="0.0074669" />
    </inertial>
    <visual>
      <origin
        xyz="0 0 0"
        rpy="0 0 0" />
      <geometry>
        <mesh
          filename="package://gantry/meshes/Z_Rot.STL" />
      </geometry>
      <material
        name="">
        <color
          rgba="0.79216 0.81961 0.93333 1" />
      </material>
    </visual>
    <collision>
      <origin
        xyz="0 0 0"
        rpy="0 0 0" />
      <geometry>
        <mesh
          filename="package://gantry/meshes/Z_Rot.STL" />
      </geometry>
    </collision>
  </link>
  <joint
    name="Z_Rot_Joint"
    type="revolute">
    <origin
      xyz="0.25743 0 0.0031492"
      rpy="0 0 0" />
    <parent
      link="Z_Motion" />
    <child
      link="Z_Rot" />
    <axis
      xyz="0 0 1" />
    <limit
      lower="-3.14"
      upper="3.14"
      effort="5"
      velocity="1" />
  </joint>
  <link
    name="Cup">
    <inertial>
      <origin
        xyz="-2.6593E-06 5.7892E-06 0.0070718"
        rpy="0 0 0" />
      <mass
        value="0.0020128" />
      <inertia
        ixx="6.7515E-08"
        ixy="-2.2805E-12"
        ixz="1.831E-12"
        iyy="6.7541E-08"
        iyz="-9.4715E-13"
        izz="6.9139E-08" />
    </inertial>
    <visual>
      <origin
        xyz="0 0 0"
        rpy="0 0 0" />
      <geometry>
        <mesh
          filename="package://gantry/meshes/Cup.STL" />
      </geometry>
      <material
        name="">
        <color
          rgba="0.79216 0.81961 0.93333 1" />
      </material>
    </visual>
    <collision>
      <origin
        xyz="0 0 0"
        rpy="0 0 0" />
      <geometry>
        <mesh
          filename="package://gantry/meshes/Cup.STL" />
      </geometry>
    </collision>
  </link>
  <joint
    name="Cup_Joint"
    type="fixed">
    <origin
      xyz="-0.0 -0.05 -0.48"
      rpy="3.1416 -0.0 0" />
    <parent
      link="Z_Rot" />
    <child
      link="Cup" />
    <axis
      xyz="0 0 1" />
  </joint>
</robot>-->


<!-- This URDF was automatically created by SolidWorks to URDF Exporter! Originally created by Stephen Brawner (brawner@gmail.com) 
     Commit Version: 1.6.0-1-g15f4949  Build Version: 1.6.7594.29634
     For more information, please see http://wiki.ros.org/sw_urdf_exporter -->
<robot name="gantry">

    <link name="world" />
    <joint name="Fix_Joint" type="fixed">
        <origin xyz="-0.0 0.00 0.0" rpy="0 0 0" />
        <parent link="world" />
        <child link="base_link" />
        <axis xyz="0 0 1" />
    </joint>
    <link name="base_link">
        
<inertial>
            <origin xyz="0.96371 1.032 1.4293" rpy="0 0 0" />
            <mass value="18.891" />
            <inertia ixx="0.68505" ixy="4.644E-15" ixz="5.1723E-15" iyy="1.4324" iyz="-4.7026E-17" izz="2.0528" />
        </inertial>

        <visual>
            <origin xyz="0 0 0" rpy="0 0 0" />
            <geometry>
                <mesh filename="package://gantry/meshes/base_link.STL" />
            </geometry>
            <material name="">
                <color rgba="0.79216 0.81961 0.93333 1" />
            </material>
        </visual>
        <collision>
            <origin xyz="0 0 0" rpy="0 0 0" />
            <geometry>
                <mesh filename="package://gantry/meshes/base_link.STL" />
            </geometry>
        </collision>
    </link>
    <link name="X_Motion">
        
<inertial>
            <origin xyz="0.2743 0.98859 0.047316" rpy="0 0 0" />
            <mass value="12.196" />
            <inertia ixx="1.9209" ixy="8.6077E-06" ixz="-1.8748E-08" iyy="1.9628" iyz="4.3927E-15" izz="0.060176" />
        </inertial>

        <visual>
            <origin xyz="0 0 0" rpy="0 0 0" />
            <geometry>
                <mesh filename="package://gantry/meshes/X_Motion.STL" />
            </geometry>
            <material name="">
                <color rgba="0.79216 0.81961 0.93333 1" />
            </material>
        </visual>
        <collision>
            <origin xyz="0 0 0" rpy="0 0 0" />
            <geometry>
                <mesh filename="package://gantry/meshes/X_Motion.STL" />
            </geometry>
        </collision>
    </link>
    <joint name="X_Joint" type="prismatic">
        <origin xyz="-0.3 0.05 0.195" rpy="1.5708 0 1.5708" />
        <parent link="base_link" />
        <child link="X_Motion" />
        <axis xyz="0 0 1" />
        <limit lower="-0.45" upper="0.48" effort="20" velocity="1" />
    </joint>
    <link name="Y_Motion">
        
<inertial>
            <origin xyz="0.060449 1.3458 0.1606" rpy="0 0 0" />
            <mass value="5.302" />
            <inertia ixx="0.061782" ixy="1.534E-08" ixz="-3.3824E-14" iyy="0.016124" iyz="-2.88E-05" izz="0.065933" />
        </inertial>

        <visual>
            <origin xyz="0 0 0" rpy="0 0 0" />
            <geometry>
                <mesh filename="package://gantry/meshes/Y_Motion.STL" />
            </geometry>
            <material name="">
                <color rgba="0.79216 0.81961 0.93333 1" />
            </material>
        </visual>
        <collision>
            <origin xyz="0 0 0" rpy="0 0 0" />
            <geometry>
                <mesh filename="package://gantry/meshes/Y_Motion.STL" />
            </geometry>
        </collision>
    </link>
    <joint name="Y_Joint" type="prismatic">
        <origin xyz="0.1 0 0.21" rpy="0 -1.5708 0" />
        <parent link="X_Motion" />
        <child link="Y_Motion" />
        <axis xyz="0 0 1" />
        <limit lower="-0.4" upper="0.4" effort="10" velocity="1" />
    </joint>
    <link name="Z_Motion">
        
<inertial>
            <origin xyz="0.241 0.1282 0.0031489" rpy="0 0 0" />
            <mass value="1.0351" />
            <inertia ixx="0.0038426" ixy="4.3556E-06" ixz="3.0941E-18" iyy="0.002377" iyz="-1.5732E-18" izz="0.0032352" />
        </inertial>

        <visual>
            <origin xyz="0 0 0" rpy="0 0 0" />
            <geometry>
                <mesh filename="package://gantry/meshes/Z_Motion.STL" />
            </geometry>
            <material name="">
                <color rgba="0.79216 0.81961 0.93333 1" />
            </material>
        </visual>
        <collision>
            <origin xyz="0 0 0" rpy="0 0 0" />
            <geometry>
                <mesh filename="package://gantry/meshes/Z_Motion.STL" />
            </geometry>
        </collision>
    </link>
    <joint name="Z_Joint" type="prismatic">
        <origin xyz="-0.0115 1.1071 0.19185" rpy="-1.5708 0 0" />
        <parent link="Y_Motion" />
        <child link="Z_Motion" />
        <axis xyz="0 0 1" />
        <limit lower="-0.2" upper="0.2" effort="50" velocity="1" />
    </joint>
    <link name="Z_Rot">
        
<inertial>
            <origin xyz="2.9681E-06 -0.2854 -7.323E-05" rpy="0 0 0" />
            <mass value="0.15277" />
            <inertia ixx="0.0077144" ixy="1.8825E-18" ixz="1.0049E-05" iyy="0.00045474" iyz="-2.4954E-17" izz="0.0074669" />
        </inertial>

        <visual>
            <origin xyz="0 0 0" rpy="0 0 0" />
            <geometry>
                <mesh filename="package://gantry/meshes/Z_Rot.STL" />
            </geometry>
            <material name="">
                <color rgba="0.79216 0.81961 0.93333 1" />
            </material>
        </visual>
        <collision>
            <origin xyz="0 0 0" rpy="0 0 0" />
            <geometry>
                <mesh filename="package://gantry/meshes/Z_Rot.STL" />
            </geometry>
        </collision>
    </link>
    <joint name="Z_Rot_Joint" type="revolute">
        <origin xyz="0.25743 0 0.0031492" rpy="0 0 0" />
        <parent link="Z_Motion" />
        <child link="Z_Rot" />
        <axis xyz="0 0 1" />
        <limit lower="-3.14" upper="3.14" effort="5" velocity="1" />
    </joint>
    <link name="Cup">
        
<inertial>
            <origin xyz="-2.6593E-06 5.7892E-06 0.0070718" rpy="0 0 0" />
            <mass value="0.0020128" />
            <inertia ixx="6.7515E-08" ixy="-2.2805E-12" ixz="1.831E-12" iyy="6.7541E-08" iyz="-9.4715E-13" izz="6.9139E-08" />
        </inertial>

        <visual>
            <origin xyz="0 0 0" rpy="0 0 0" />
            <geometry>
                <mesh filename="package://gantry/meshes/Cup.STL" />
            </geometry>
            <material name="">
                <color rgba="0.79216 0.81961 0.93333 1" />
            </material>
        </visual>
        <collision>
            <origin xyz="0 0 0" rpy="0 0 0" />
            <geometry>
                <mesh filename="package://gantry/meshes/Cup.STL" />
            </geometry>
        </collision>
    </link>
    <joint name="Cup_Joint" type="fixed">
        <origin xyz="-0.0 -0.05 -0.48" rpy="3.1416 -0.0 0" />
        <parent link="Z_Rot" />
        <child link="Cup" />
        <axis xyz="0 0 1" />
    </joint>
    
<transmission name="trans_X_Joint">
        <type>transmission_interface/SimpleTransmission</type>
        <joint name="X_Joint">
            <hardwareInterface>hardware_interface/PositionJointInterface</hardwareInterface>
        </joint>
        <actuator name="X_Joint_motor">
            <hardwareInterface>hardware_interface/PositionJointInterface</hardwareInterface>
            <mechanicalReduction>1</mechanicalReduction>
        </actuator>
    </transmission>
    <transmission name="trans_Y_Joint">
        <type>transmission_interface/SimpleTransmission</type>
        <joint name="Y_Joint">
            <hardwareInterface>hardware_interface/PositionJointInterface</hardwareInterface>
        </joint>
        <actuator name="Y_Joint_motor">
            <hardwareInterface>hardware_interface/PositionJointInterface</hardwareInterface>
            <mechanicalReduction>1</mechanicalReduction>
        </actuator>
    </transmission>
    <transmission name="trans_Z_Joint">
        <type>transmission_interface/SimpleTransmission</type>
        <joint name="Z_Joint">
            <hardwareInterface>hardware_interface/PositionJointInterface</hardwareInterface>
        </joint>
        <actuator name="Z_Joint_motor">
            <hardwareInterface>hardware_interface/PositionJointInterface</hardwareInterface>
            <mechanicalReduction>1</mechanicalReduction>
        </actuator>
    </transmission>
    <transmission name="trans_Z_Rot_Joint">
        <type>transmission_interface/SimpleTransmission</type>
        <joint name="Z_Rot_Joint">
            <hardwareInterface>hardware_interface/PositionJointInterface</hardwareInterface>
        </joint>
        <actuator name="Z_Rot_Joint_motor">
            <hardwareInterface>hardware_interface/PositionJointInterface</hardwareInterface>
            <mechanicalReduction>1</mechanicalReduction>
        </actuator>
    </transmission>
    <gazebo>
        <plugin name="gazebo_ros_control" filename="libgazebo_ros_control.so">
            <robotNamespace>/</robotNamespace>
        </plugin>
    </gazebo>
</robot>









<!-- END -->
